from _0_cpp_exception import foo

foo()
# generates an exception

